<?xml version="1.0" encoding="UTF-8"?>
<testsuite name="pt.isel.ls.utils.TryResponseTest" tests="5" skipped="0" failures="0" errors="0" timestamp="2024-03-27T14:29:48" hostname="LAPTOP-RPUNL8UP" time="0.016">
  <properties/>
  <testcase name="returning status internal server error on try response test with an exception()" classname="pt.isel.ls.utils.TryResponseTest" time="0.008"/>
  <testcase name="comparing contend of try response body test with exception message()" classname="pt.isel.ls.utils.TryResponseTest" time="0.002"/>
  <testcase name="comparing contend of try response test with an exception without message()" classname="pt.isel.ls.utils.TryResponseTest" time="0.001"/>
  <testcase name="returning status ok with try response status test()" classname="pt.isel.ls.utils.TryResponseTest" time="0.0"/>
  <testcase name="comparing contend of try response body test()" classname="pt.isel.ls.utils.TryResponseTest" time="0.002"/>
  <system-out><![CDATA[]]></system-out>
  <system-err><![CDATA[]]></system-err>
</testsuite>
